<?xml version='1.0'?>
<sdf version='1.7'>
  <model name='abb6640'>
    <link name='base_link'>
      <pose>0 0 0 0 -0 0</pose>
      <inertial>
        <pose>0 0 0.107 0 -0 0</pose>
        <mass>254.138</mass>
        <inertia>
          <ixx>9.459</ixx>
          <ixy>-0.018</ixy>
          <ixz>-0.297</ixz>
          <iyy>9.18</iyy>
          <iyz>0.003</iyz>
          <izz>16.946</izz>
        </inertia>
      </inertial>
      <self_collide>0</self_collide>
      <enable_wind>0</enable_wind>
      <kinematic>0</kinematic>
      <visual name='base_link_fixed_joint_lump__visual_visual'>
        <pose>0 0 0 0 -0 0</pose>
        <geometry>
          <mesh>
            <scale>1 1 1</scale>
            <uri>model://abb6640/meshes/visual/Base.stl</uri>
          </mesh>
        </geometry>
        <material>
          <shader type='pixel'/>
        </material>
        <transparency>0</transparency>
        <cast_shadows>1</cast_shadows>
      </visual>
     
    </link>
    <link name='link_1'>
      <pose>0 -0 0.78 0 -0 0</pose>
      <inertial>
        <pose>-0.011 -0.038 -0.214 0 -0 0</pose>
        <mass>469.323</mass>
        <inertia>
          <ixx>29.062</ixx>
          <ixy>11.518</ixy>
          <ixz>3.154</ixz>
          <iyy>50.561</iyy>
          <iyz>-0.943</iyz>
          <izz>46.087</izz>
        </inertia>
      </inertial>
      <self_collide>0</self_collide>
      <enable_wind>0</enable_wind>
      <kinematic>0</kinematic>
      <visual name='link_1_fixed_joint_lump__visual_visual'>
        <pose>0 0 -0.78 0 -0 0</pose>
        <geometry>
          <mesh>
            <scale>1 1 1</scale>
            <uri>model://abb6640/meshes/visual/Link1.stl</uri>
          </mesh>
        </geometry>
        <material>
          <shader type='pixel'/>
        </material>
        <transparency>0</transparency>
        <cast_shadows>1</cast_shadows>
      </visual>
      <visual name='link_1_fixed_joint_lump__visual2_visual_1'>
        <pose>0 0 -0.78 0 -0 0</pose>
        <geometry>
          <mesh>
            <scale>1 1 1</scale>
            <uri>model://abb6640/meshes/visual/LinkD1.stl</uri>
          </mesh>
        </geometry>
        <material>
          <shader type='pixel'/>
        </material>
        <transparency>0</transparency>
        <cast_shadows>1</cast_shadows>
      </visual>
      
    </link>
    <link name='link_2'>
      <pose>0.32 -0 0.78 0 -0 0</pose>
      <inertial>
        <pose>0.007 -0.174 0.441 0 -0 0</pose>
        <mass>153.009</mass>
        <inertia>
          <ixx>37.57</ixx>
          <ixy>-0.08</ixy>
          <ixz>-0.145</ixz>
          <iyy>37.47</iyy>
          <iyz>-5.325</iyz>
          <izz>3.526</izz>
        </inertia>
      </inertial>
      <self_collide>0</self_collide>
      <enable_wind>0</enable_wind>
      <kinematic>0</kinematic>
      <visual name='link_2_fixed_joint_lump__visual_visual'>
        <pose>-0.32 0 -0.78 0 -0 0</pose>
        <geometry>
          <mesh>
            <scale>1 1 1</scale>
            <uri>model://abb6640/meshes/visual/Link2.stl</uri>
          </mesh>
        </geometry>
        <material>
          <shader type='pixel'/>
        </material>
        <transparency>0</transparency>
        <cast_shadows>1</cast_shadows>
      </visual>
      
    </link>
    <link name='link_3'>
      <pose>0.32 0 1.855 0 -0 0</pose>
      <inertial>
        <pose>-0.045 0.022 0.139 0 -0 0</pose>
        <mass>212.29</mass>
        <inertia>
          <ixx>6.575</ixx>
          <ixy>-1.029</ixy>
          <ixz>-0.621</ixz>
          <iyy>6.667</iyy>
          <iyz>0.976</iyz>
          <izz>7.699</izz>
        </inertia>
      </inertial>
      <self_collide>0</self_collide>
      <enable_wind>0</enable_wind>
      <kinematic>0</kinematic>
      <visual name='link_3_fixed_joint_lump__visual_visual'>
        <pose>-0.32 0 -1.855 0 -0 0</pose>
        <geometry>
          <mesh>
            <scale>1 1 1</scale>
            <uri>model://abb6640/meshes/visual/Link3.stl</uri>
          </mesh>
        </geometry>
        <material>
          <shader type='pixel'/>
        </material>
        <transparency>0</transparency>
        <cast_shadows>1</cast_shadows>
      </visual>
      
    </link>
    <link name='link_4'>
      <pose>0.32 0 2.055 0 -0 0</pose>
      <inertial>
        <pose>0.606 -0.008 0 0 -0 0</pose>
        <mass>185.22</mass>
        <inertia>
          <ixx>1.744</ixx>
          <ixy>-0.722</ixy>
          <ixz>0.014</ixz>
          <iyy>30.392</iyy>
          <iyz>-0.005</iyz>
          <izz>31.078</izz>
        </inertia>
      </inertial>
      <self_collide>0</self_collide>
      <enable_wind>0</enable_wind>
      <kinematic>0</kinematic>
      <visual name='link_4_fixed_joint_lump__visual_visual'>
        <pose>-0.32 0 -2.055 0 -0 0</pose>
        <geometry>
          <mesh>
            <scale>1 1 1</scale>
            <uri>model://abb6640/meshes/visual/Link4.stl</uri>
          </mesh>
        </geometry>
        <material>
          <shader type='pixel'/>
        </material>
        <transparency>0</transparency>
        <cast_shadows>1</cast_shadows>
      </visual>
      
    </link>
    <link name='link_5'>
      <pose>1.462 0 2.055 0 -0 0</pose>
      <inertial>
        <pose>0.039 0.001 0 0 -0 0</pose>
        <mass>26.117</mass>
        <inertia>
          <ixx>0.106</ixx>
          <ixy>-0.005</ixy>
          <ixz>0</ixz>
          <iyy>0.207</iyy>
          <iyz>0</iyz>
          <izz>0.218</izz>
        </inertia>
      </inertial>
      <self_collide>0</self_collide>
      <enable_wind>0</enable_wind>
      <kinematic>0</kinematic>
      <visual name='link_5_fixed_joint_lump__visual_visual'>
        <pose>-1.462 0 -2.055 0 -0 0</pose>
        <geometry>
          <mesh>
            <scale>1 1 1</scale>
            <uri>model://abb6640/meshes/visual/Link5.stl</uri>
          </mesh>
        </geometry>
        <material>
          <shader type='pixel'/>
        </material>
        <transparency>0</transparency>
        <cast_shadows>1</cast_shadows>
      </visual>
      
    </link>
    <link name='link_6'>
      <pose>1.662 0 2.055 0 -0 0</pose>
      <inertial>
        <pose>-0.019 -0.001 0 0 -0 0</pose>
        <mass>3.371</mass>
        <inertia>
          <ixx>0.017</ixx>
          <ixy>0</ixy>
          <ixz>0</ixz>
          <iyy>0.009</iyy>
          <iyz>0</iyz>
          <izz>0.009</izz>
        </inertia>
      </inertial>
      <self_collide>0</self_collide>
      <enable_wind>0</enable_wind>
      <kinematic>0</kinematic>
      <visual name='link_6_fixed_joint_lump__visual_visual'>
        <pose>-1.662 0 -2.055 0 -0 0</pose>
        <geometry>
          <mesh>
            <scale>1 1 1</scale>
            <uri>model://abb6640/meshes/visual/Link6.stl</uri>
          </mesh>
        </geometry>
        <material>
          <shader type='pixel'/>
        </material>
        <transparency>0</transparency>
        <cast_shadows>1</cast_shadows>
      </visual>
    </link>

    <link name='paint_gun'>
      <pose>1.662 0 2.055 0 1.57079632679 0</pose>
      <inertial>
        <pose>0 0 0 0 0 0</pose>
        <mass>0.137</mass>
        <inertia>
          <ixx>0.001</ixx>
          <ixy>0</ixy>
          <ixz>0</ixz>
          <iyy>0.001</iyy>
          <iyz>0</iyz>
          <izz>0.001</izz>
        </inertia>
      </inertial>
      <self_collide>0</self_collide>
      <enable_wind>0</enable_wind>
      <kinematic>0</kinematic>
      <visual name='paint_gun_visual'>
        <pose>0 0 0 0 -0 0</pose>
        <geometry>
          <mesh>
            <scale>0.001 0.001 0.001</scale>
            <uri>model://paint_gun.stl</uri>
          </mesh>
        </geometry>
        <material>
          <shader type='pixel'/>
        </material>
        <transparency>0</transparency>
        <cast_shadows>1</cast_shadows>
      </visual>
    </link>

    <!-- <link name='generic_fan_blade'>
      <pose>1.674 -0.3 2.236 -1.0472 0 1.57</pose>
      <inertial>
        <pose>0 0 0 0 0 0</pose>
        <mass>0.137</mass>
        <inertia>
          <ixx>0.001</ixx>
          <ixy>0</ixy>
          <ixz>0</ixz>
          <iyy>0.001</iyy>
          <iyz>0</iyz>
          <izz>0.001</izz>
        </inertia>
      </inertial>
      <self_collide>0</self_collide>
      <enable_wind>0</enable_wind>
      <kinematic>0</kinematic>
      <visual name='generic_fan_blade_visual'>
        <pose>0 0 0 0 -0 0</pose>
        <geometry>
          <mesh>
            <scale>0.001 0.001 0.001</scale>
            <uri>model://abb6650s2/meshes/visual/generic_fan_blade.stl</uri>
          </mesh>
        </geometry>
        <material>
          <shader type='pixel'/>
        </material>
        <transparency>0</transparency>
        <cast_shadows>1</cast_shadows>
      </visual>
    </link> -->

    
    <joint name='joint_1' type='revolute'>
      <parent>base_link</parent>
      <child>link_1</child>
      <pose>0 0 0 0 -0 0</pose>
      <axis>
        <xyz>0 0 1</xyz>
        <limit>
          <lower>-2.967</lower>
          <upper>2.967</upper>
          <effort>0</effort>
          <velocity>1.7453</velocity>
        </limit>
        <dynamics>
          <spring_reference>0</spring_reference>
          <spring_stiffness>0</spring_stiffness>
          <damping>0</damping>
          <friction>0</friction>
        </dynamics>
      </axis>
      <physics>
        <ode>
          <limit>
            <cfm>0</cfm>
            <erp>0.2</erp>
          </limit>
          <suspension>
            <cfm>0</cfm>
            <erp>0.2</erp>
          </suspension>
        </ode>
      </physics>
    </joint>
    <joint name='joint_2' type='revolute'>
      <parent>link_1</parent>
      <child>link_2</child>
      <pose>0 0 0 0 -0 0</pose>
      <axis>
        <xyz>0 1 0</xyz>
        <limit>
          <lower>-1.134</lower>
          <upper>1.4855</upper>
          <effort>0</effort>
          <velocity>1.5707</velocity>
        </limit>
        <dynamics>
          <spring_reference>0</spring_reference>
          <spring_stiffness>0</spring_stiffness>
          <damping>0</damping>
          <friction>0</friction>
        </dynamics>
      </axis>
      <physics>
        <ode>
          <limit>
            <cfm>0</cfm>
            <erp>0.2</erp>
          </limit>
          <suspension>
            <cfm>0</cfm>
            <erp>0.2</erp>
          </suspension>
        </ode>
      </physics>
    </joint>
    <joint name='joint_3' type='revolute'>
      <parent>link_2</parent>
      <child>link_3</child>
      <pose>0 0 0 0 -0 0</pose>
      <axis>
        <xyz>0 1 0</xyz>
        <limit>
          <lower>-3.142</lower>
          <upper>1.222</upper>
          <effort>0</effort>
          <velocity>1.5707</velocity>
        </limit>
        <dynamics>
          <spring_reference>0</spring_reference>
          <spring_stiffness>0</spring_stiffness>
          <damping>0</damping>
          <friction>0</friction>
        </dynamics>
      </axis>
      <physics>
        <ode>
          <limit>
            <cfm>0</cfm>
            <erp>0.2</erp>
          </limit>
          <suspension>
            <cfm>0</cfm>
            <erp>0.2</erp>
          </suspension>
        </ode>
      </physics>
    </joint>
    <joint name='joint_4' type='revolute'>
      <parent>link_3</parent>
      <child>link_4</child>
      <pose>0 0 0 0 -0 0</pose>
      <axis>
        <xyz>1 0 0</xyz>
        <limit>
          <lower>-5.236</lower>
          <upper>5.236</upper>
          <effort>0</effort>
          <velocity>2.9671</velocity>
        </limit>
        <dynamics>
          <spring_reference>0</spring_reference>
          <spring_stiffness>0</spring_stiffness>
          <damping>0</damping>
          <friction>0</friction>
        </dynamics>
      </axis>
      <physics>
        <ode>
          <limit>
            <cfm>0</cfm>
            <erp>0.2</erp>
          </limit>
          <suspension>
            <cfm>0</cfm>
            <erp>0.2</erp>
          </suspension>
        </ode>
      </physics>
    </joint>
    <joint name='joint_5' type='revolute'>
      <parent>link_4</parent>
      <child>link_5</child>
      <pose>0 0 0 0 -0 0</pose>
      <axis>
        <xyz>0 1 0</xyz>
        <limit>
          <lower>-2.094</lower>
          <upper>2.094</upper>
          <effort>0</effort>
          <velocity>2.4435</velocity>
        </limit>
        <dynamics>
          <spring_reference>0</spring_reference>
          <spring_stiffness>0</spring_stiffness>
          <damping>0</damping>
          <friction>0</friction>
        </dynamics>
      </axis>
      <physics>
        <ode>
          <limit>
            <cfm>0</cfm>
            <erp>0.2</erp>
          </limit>
          <suspension>
            <cfm>0</cfm>
            <erp>0.2</erp>
          </suspension>
        </ode>
      </physics>
    </joint>
    <joint name='joint_6' type='revolute'>
      <parent>link_5</parent>
      <child>link_6</child>
      <pose>0 0 0 0 -0 0</pose>
      <axis>
        <xyz>1 0 0</xyz>
        <limit>
          <lower>-6.283</lower>
          <upper>6.283</upper>
          <effort>0</effort>
          <velocity>3.3161</velocity>
        </limit>
        <dynamics>
          <spring_reference>0</spring_reference>
          <spring_stiffness>0</spring_stiffness>
          <damping>0</damping>
          <friction>0</friction>
        </dynamics>
      </axis>
      <physics>
        <ode>
          <limit>
            <cfm>0</cfm>
            <erp>0.2</erp>
          </limit>
          <suspension>
            <cfm>0</cfm>
            <erp>0.2</erp>
          </suspension>
        </ode>
      </physics>
    </joint>
    <joint name='eef_joint' type='fixed'>
      <parent>link_6</parent>
      <child>paint_gun</child>
    </joint>
 <!--    <joint name='eef_joint2' type='fixed'>
      <parent>link_6</parent>
      <child>generic_fan_blade</child>
    </joint> -->

    <joint name='fix to ground' type='fixed'>
      <parent>world</parent>
      <child>base_link</child>
    </joint>
    <static>0</static>
    <allow_auto_disable>1</allow_auto_disable>
  </model>
</sdf>
