<?xml version='1.0'?>
<sdf version='1.7'>
  <model name='abb6650s2'>
    <link name='abb_pedestal'>
      <inertial>
        <pose>0 0 0 0 -0 0</pose>
        <mass>14.7742</mass>
        <inertia>
          <ixx>0.247831</ixx>
          <ixy>0.000495482</ixy>
          <ixz>0.000311158</ixz>
          <iyy>0.285523</iyy>
          <iyz>-0.000245375</iyz>
          <izz>0.255433</izz>
        </inertia>
      </inertial>
      <self_collide>0</self_collide>
      <enable_wind>0</enable_wind>
      <kinematic>0</kinematic>
      <pose>0 0 0 0 -0 0</pose>
      <visual name='abb_pedestal_visual1'>
        <pose>0 0 0 0 -0 0</pose>
        <geometry>
          <mesh>
            <scale>1 1 1</scale>
            <uri>model://abb6650s2/meshes/visual/base_link.stl</uri>
          </mesh>
        </geometry>
        <material>
          <shader type='pixel'/>
        </material>
        <transparency>0</transparency>
        <cast_shadows>1</cast_shadows>
      </visual>
      <visual name='abb_pedestal_visual2'>
        <pose>0 0 -0.5 0 -0 0</pose>
        <geometry>
          <cylinder>
            <length>1</length>
            <radius>0.2</radius>
          </cylinder>
        </geometry>
        <material>
          <shader type='pixel'/>
        </material>
        <transparency>0</transparency>
        <cast_shadows>1</cast_shadows>
      </visual>
    </link>
    <link name='link_1'>
      <pose>0 0 0.63 0 -0 0</pose>
      <inertial>
        <pose>0 0 0 0 -0 0</pose>
        <mass>11.8419</mass>
        <inertia>
          <ixx>0.11194</ixx>
          <ixy>-4.54988e-05</ixy>
          <ixz>0.000280961</ixz>
          <iyy>0.0915159</iyy>
          <iyz>-0.000109905</iyz>
          <izz>0.0876456</izz>
        </inertia>
      </inertial>
      <self_collide>0</self_collide>
      <enable_wind>0</enable_wind>
      <kinematic>0</kinematic>
      <visual name='abb_link1_visual'>
        <pose>0 0 0 0 -0 0</pose>
        <geometry>
          <mesh>
            <scale>1 1 1</scale>
            <uri>model://abb6650s2/meshes/visual/link_1.stl</uri>
          </mesh>
        </geometry>
        <material>
          <shader type='pixel'/>
        </material>
        <transparency>0</transparency>
        <cast_shadows>1</cast_shadows>
      </visual>
    </link>
    <link name='link_2'>
      <pose>0.6 0 0.63 0 -0 0</pose>
      <inertial>
        <pose>0 0 0 0 -0 0</pose>
        <mass>17.5394</mass>
        <inertia>
          <ixx>0.493558</ixx>
          <ixy>1.32136e-05</ixy>
          <ixz>0.000209024</ixz>
          <iyy>0.462939</iyy>
          <iyz>-0.00179901</iyz>
          <izz>0.0894214</izz>
        </inertia>
      </inertial>
      <self_collide>0</self_collide>
      <enable_wind>0</enable_wind>
      <kinematic>0</kinematic>
      <visual name='abb_link2_visual'>
        <pose>0 0 0 0 -0 0</pose>
        <geometry>
          <mesh>
            <scale>1 1 1</scale>
            <uri>model://abb6650s2/meshes/visual/link_2.stl</uri>
          </mesh>
        </geometry>
        <material>
          <shader type='pixel'/>
        </material>
        <transparency>0</transparency>
        <cast_shadows>1</cast_shadows>
      </visual>
    </link>
    <link name='link_3'>
      <pose>0.6 0 1.91 0 -0 0</pose>
      <inertial>
        <pose>0 0 0 0 -0 0</pose>
        <mass>7.46365</mass>
        <inertia>
          <ixx>0.0252424</ixx>
          <ixy>0.000142737</ixy>
          <ixz>-0.00565542</ixz>
          <iyy>0.0906438</iyy>
          <iyz>0.000142213</iyz>
          <izz>0.0825079</izz>
        </inertia>
      </inertial>
      <self_collide>0</self_collide>
      <enable_wind>0</enable_wind>
      <kinematic>0</kinematic>
      <visual name='abb_link3_visual'>
        <pose>0 0 0 0 -0 0</pose>
        <geometry>
          <mesh>
            <scale>1 1 1</scale>
            <uri>model://abb6650s2/meshes/visual/link_3.stl</uri>
          </mesh>
        </geometry>
        <material>
          <shader type='pixel'/>
        </material>
        <transparency>0</transparency>
        <cast_shadows>1</cast_shadows>
      </visual>
    </link>
    <link name='link_4'>
      <pose>0 0 2.11 0 -0 0</pose>
      <inertial>
        <pose>0 0 0 0 -0 0</pose>
        <mass>2.74436</mass>
        <inertia>
          <ixx>0.00573099</ixx>
          <ixy>-0.000131119</ixy>
          <ixz>0.000380232</ixz>
          <iyy>0.0118352</iyy>
          <iyz>-2.26565e-05</iyz>
          <izz>0.0114428</izz>
        </inertia>
      </inertial>
      <self_collide>0</self_collide>
      <enable_wind>0</enable_wind>
      <kinematic>0</kinematic>
      <visual name='abb_link4_visual'>
        <pose>0 0 0 0 -0 0</pose>
        <geometry>
          <mesh>
            <scale>1 1 1</scale>
            <uri>model://abb6650s2/meshes/visual/link_4.stl</uri>
          </mesh>
        </geometry>
        <material>
          <shader type='pixel'/>
        </material>
        <transparency>0</transparency>
        <cast_shadows>1</cast_shadows>
      </visual>
    </link>
    <link name='link_5'>
      <pose>2.192 0 2.11 0 -0 0</pose>
      <inertial>
        <pose>0 0 0 0 -0 0</pose>
        <mass>0.62953</mass>
        <inertia>
          <ixx>0.000502815</ixx>
          <ixy>-1.03173e-05</ixy>
          <ixz>-8.74347e-08</ixz>
          <iyy>0.00108856</iyy>
          <iyz>2.07657e-07</iyz>
          <izz>0.000918873</izz>
        </inertia>
      </inertial>
      <self_collide>0</self_collide>
      <enable_wind>0</enable_wind>
      <kinematic>0</kinematic>
      <visual name='abb_link5_visual'>
        <pose>0 0 0 0 -0 0</pose>
        <geometry>
          <mesh>
            <scale>1 1 1</scale>
            <uri>model://abb6650s2/meshes/visual/link_5.stl</uri>
          </mesh>
        </geometry>
        <material>
          <shader type='pixel'/>
        </material>
        <transparency>0</transparency>
        <cast_shadows>1</cast_shadows>
      </visual>
    </link>
    <link name='link_6'>
      <pose>2.392 0 2.11 0 -0 0</pose>
      <inertial>
        <pose>0 0 0 0 -0 0</pose>
        <mass>0.137</mass>
        <inertia>
          <ixx>0.001</ixx>
          <ixy>0</ixy>
          <ixz>0</ixz>
          <iyy>0.001</iyy>
          <iyz>0</iyz>
          <izz>0.001</izz>
        </inertia>
      </inertial>
      <self_collide>0</self_collide>
      <enable_wind>0</enable_wind>
      <kinematic>0</kinematic>
      <visual name='abb_link6_visual'>
        <pose>0 0 0 0 -0 0</pose>
        <geometry>
          <mesh>
            <scale>1 1 1</scale>
            <uri>model://abb6650s2/meshes/visual/link_6.stl</uri>
          </mesh>
        </geometry>
        <material>
          <shader type='pixel'/>
        </material>
        <transparency>0</transparency>
        <cast_shadows>1</cast_shadows>
      </visual>
    </link>

    <link name='paint_gun'>
      <pose>2.392 0 2.11 0 1.57079632679 0</pose>
      <inertial>
        <pose>0 0 0 0 0 0</pose>
        <mass>0.137</mass>
        <inertia>
          <ixx>0.001</ixx>
          <ixy>0</ixy>
          <ixz>0</ixz>
          <iyy>0.001</iyy>
          <iyz>0</iyz>
          <izz>0.001</izz>
        </inertia>
      </inertial>
      <self_collide>0</self_collide>
      <enable_wind>0</enable_wind>
      <kinematic>0</kinematic>
      <visual name='paint_gun_visual'>
        <pose>0 0 0 0 -0 0</pose>
        <geometry>
          <mesh>
            <scale>0.001 0.001 0.001</scale>
            <uri>model://abb6650s1/meshes/visual/paint_gun.stl</uri>
          </mesh>
        </geometry>
        <material>
          <shader type='pixel'/>
        </material>
        <transparency>0</transparency>
        <cast_shadows>1</cast_shadows>
      </visual>
    </link>

    <link name='generic_fan_blade'>
      <pose>2.404 -0.3 2.291 -1.0472 0 1.57</pose>
      <inertial>
        <pose>0 0 0 0 0 0</pose>
        <mass>0.137</mass>
        <inertia>
          <ixx>0.001</ixx>
          <ixy>0</ixy>
          <ixz>0</ixz>
          <iyy>0.001</iyy>
          <iyz>0</iyz>
          <izz>0.001</izz>
        </inertia>
      </inertial>
      <self_collide>0</self_collide>
      <enable_wind>0</enable_wind>
      <kinematic>0</kinematic>
      <visual name='generic_fan_blade_visual'>
        <pose>0 0 0 0 -0 0</pose>
        <geometry>
          <mesh>
            <scale>0.001 0.001 0.001</scale>
            <uri>model://abb6650s2/meshes/visual/generic_fan_blade.stl</uri>
          </mesh>
        </geometry>
        <material>
          <shader type='pixel'/>
        </material>
        <transparency>0</transparency>
        <cast_shadows>1</cast_shadows>
      </visual>
    </link>


    <joint name='joint_1' type='revolute'>
      <parent>abb_pedestal</parent>
      <child>link_1</child>
      <pose>0 0 0 0 -0 0</pose>
      <axis>
        <xyz>0 0 1</xyz>
        <limit>
          <lower>-2.967</lower>
          <upper>2.967</upper>
          <effort>1000</effort>
          <velocity>5.027</velocity>
        </limit>
        <dynamics>
          <spring_reference>0</spring_reference>
          <spring_stiffness>0</spring_stiffness>
          <damping>0</damping>
          <friction>0</friction>
        </dynamics>
      </axis>
      <physics>
        <ode>
          <limit>
            <cfm>0</cfm>
            <erp>0.2</erp>
          </limit>
          <suspension>
            <cfm>0</cfm>
            <erp>0.2</erp>
          </suspension>
        </ode>
      </physics>
    </joint>
    <joint name='joint_2' type='revolute'>
      <parent>link_1</parent>
      <child>link_2</child>
      <pose>0 0 0 0 -0 0</pose>
      <axis>
        <xyz>0 1 0</xyz>
        <limit>
          <lower>-1.745</lower>
          <upper>2.269</upper>
          <effort>1000</effort>
          <velocity>4.189</velocity>
        </limit>
        <dynamics>
          <spring_reference>0</spring_reference>
          <spring_stiffness>0</spring_stiffness>
          <damping>0</damping>
          <friction>0</friction>
        </dynamics>
      </axis>
      <physics>
        <ode>
          <limit>
            <cfm>0</cfm>
            <erp>0.2</erp>
          </limit>
          <suspension>
            <cfm>0</cfm>
            <erp>0.2</erp>
          </suspension>
        </ode>
      </physics>
    </joint>
    <joint name='joint_3' type='revolute'>
      <parent>link_2</parent>
      <child>link_3</child>
      <pose>0 0 -0 0 -0 0</pose>
      <axis>
        <xyz>0 1 0</xyz>
        <limit>
          <lower>-3.491</lower>
          <upper>1.222</upper>
          <effort>1000</effort>
          <velocity>5.236</velocity>
        </limit>
        <dynamics>
          <spring_reference>0</spring_reference>
          <spring_stiffness>0</spring_stiffness>
          <damping>0</damping>
          <friction>0</friction>
        </dynamics>
      </axis>
      <physics>
        <ode>
          <limit>
            <cfm>0</cfm>
            <erp>0.2</erp>
          </limit>
          <suspension>
            <cfm>0</cfm>
            <erp>0.2</erp>
          </suspension>
        </ode>
      </physics>
    </joint>
    <joint name='joint_4' type='revolute'>
      <parent>link_3</parent>
      <child>link_4</child>
      <pose>0.6 0 0 0 -0 0</pose>
      <axis>
        <xyz>1 0 0</xyz>
        <limit>
          <lower>-4.712</lower>
          <upper>4.712</upper>
          <effort>1000</effort>
          <velocity>6.981</velocity>
        </limit>
        <dynamics>
          <spring_reference>0</spring_reference>
          <spring_stiffness>0</spring_stiffness>
          <damping>0</damping>
          <friction>0</friction>
        </dynamics>
      </axis>
      <physics>
        <ode>
          <limit>
            <cfm>0</cfm>
            <erp>0.2</erp>
          </limit>
          <suspension>
            <cfm>0</cfm>
            <erp>0.2</erp>
          </suspension>
        </ode>
      </physics>
    </joint>
    <joint name='joint_5' type='revolute'>
      <parent>link_4</parent>
      <child>link_5</child>
      <pose>0 0 0 0 -0 0</pose>
      <axis>
        <xyz>0 1 0</xyz>
        <limit>
          <lower>-2.269</lower>
          <upper>2.269</upper>
          <effort>1000</effort>
          <velocity>7.069</velocity>
        </limit>
        <dynamics>
          <spring_reference>0</spring_reference>
          <spring_stiffness>0</spring_stiffness>
          <damping>0</damping>
          <friction>0</friction>
        </dynamics>
      </axis>
      <physics>
        <ode>
          <limit>
            <cfm>0</cfm>
            <erp>0.2</erp>
          </limit>
          <suspension>
            <cfm>0</cfm>
            <erp>0.2</erp>
          </suspension>
        </ode>
      </physics>
    </joint>
    <joint name='joint_6' type='revolute'>
      <parent>link_5</parent>
      <child>link_6</child>
      <pose>-0 0 0 0 -0 0</pose>
      <axis>
        <xyz>1 0 0</xyz>
        <limit>
          <lower>-6.283</lower>
          <upper>6.283</upper>
          <effort>1000</effort>
          <velocity>10.472</velocity>
        </limit>
        <dynamics>
          <spring_reference>0</spring_reference>
          <spring_stiffness>0</spring_stiffness>
          <damping>0</damping>
          <friction>0</friction>
        </dynamics>
      </axis>
      <physics>
        <ode>
          <limit>
            <cfm>0</cfm>
            <erp>0.2</erp>
          </limit>
          <suspension>
            <cfm>0</cfm>
            <erp>0.2</erp>
          </suspension>
        </ode>
      </physics>
    </joint>

    <joint name='eef_joint' type='fixed'>
      <parent>link_6</parent>
      <child>generic_fan_blade</child>
    </joint>

    <joint name='eef_joint2' type='fixed'>
      <parent>link_6</parent>
      <child>paint_gun</child>
    </joint>


    <joint name='fix to ground' type='fixed'>
      <parent>world</parent>
      <child>abb_pedestal</child>
    </joint>
    <allow_auto_disable>1</allow_auto_disable>
  </model>
</sdf>
