<?xml version="1.0" ?>
<!-- =================================================================================== -->
<!-- |    This document was autogenerated by xacro from m710ic50.xacro                 | -->
<!-- |    EDITING THIS FILE BY HAND IS NOT RECOMMENDED                                 | -->
<!-- =================================================================================== -->
<robot name="fanuc_m710ic50">
  <!-- links: main serial chain -->
  <link name="base_link">
    <visual>
      <origin rpy="0 0 0" xyz="0 0 0"/>
      <geometry>
        <mesh filename="package://fanuc_m710ic_support/meshes/m710ic50/visual/base_link.stl"/>
      </geometry>
      <material name="">
        <color rgba="0.15 0.15 0.15 1.0"/>
      </material>
    </visual>
    <collision>
      <origin rpy="0 0 0" xyz="0 0 0"/>
      <geometry>
        <mesh filename="package://fanuc_m710ic_support/meshes/m710ic50/collision/base_link.stl"/>
      </geometry>
    </collision>
    <inertial>
      <origin rpy="0 0 0" xyz="-0.0494077 -0.0002174 0.1192173 "/>
      <mass value="70.202263864"/>
      <inertia ixx="1.8664685596000001" ixy="0.00508834392" ixz="0.028802781360000005" iyy="1.9069223237600001" iyz="-0.0023828061600000006" izz="3.0367021758400004"/>
    </inertial>
  </link>
  <link name="link_1">
    <visual>
      <origin rpy="0 0 0" xyz="0 0 0"/>
      <geometry>
        <mesh filename="package://fanuc_m710ic_support/meshes/m710ic50/visual/link_1.stl"/>
      </geometry>
      <material name="">
        <color rgba="0.96 0.76 0.13 1.0"/>
      </material>
    </visual>
    <collision>
      <origin rpy="0 0 0" xyz="0 0 0"/>
      <geometry>
        <mesh filename="package://fanuc_m710ic_support/meshes/m710ic50/collision/link_1.stl"/>
      </geometry>
    </collision>
    <inertial>
      <origin rpy="0 0 0" xyz="0.0513947 -0.0070627 -0.1050768 "/>
      <mass value="108.644639352"/>
      <inertia ixx="4.054015038080001" ixy="-0.1794434332" ixz="-0.27176029648" iyy="3.4557061160000004" iyz="0.11914931032000001" izz="4.337960095200001"/>
    </inertial>
  </link>
  <link name="link_2">
    <visual>
      <origin rpy="0 0 0" xyz="0 0 0"/>
      <geometry>
        <mesh filename="package://fanuc_m710ic_support/meshes/m710ic50/visual/link_2.stl"/>
      </geometry>
      <material name="">
        <color rgba="0.96 0.76 0.13 1.0"/>
      </material>
    </visual>
    <collision>
      <origin rpy="0 0 0" xyz="0 0 0"/>
      <geometry>
        <mesh filename="package://fanuc_m710ic_support/meshes/m710ic50/collision/link_2.stl"/>
      </geometry>
    </collision>
    <inertial>
      <origin rpy="0 0 0" xyz="0.0030967 0.1539055 0.3439080 "/>
      <mass value="48.872714959999996"/>
      <inertia ixx="4.208170315120001" ixy="0.012389246400000001" ixz="0.0021019107200000004" iyy="4.351861899040001" iyz="-0.16360847808000004" izz="0.4034845588000001"/>
    </inertial>
  </link>
  <link name="link_3">
    <visual>
      <origin rpy="0 0 0" xyz="0 0 0"/>
      <geometry>
        <mesh filename="package://fanuc_m710ic_support/meshes/m710ic50/visual/link_3.stl"/>
      </geometry>
      <material name="">
        <color rgba="0.96 0.76 0.13 1.0"/>
      </material>
    </visual>
    <collision>
      <origin rpy="0 0 0" xyz="0 0 0"/>
      <geometry>
        <mesh filename="package://fanuc_m710ic_support/meshes/m710ic50/collision/link_3.stl"/>
      </geometry>
    </collision>
    <inertial>
      <origin rpy="0 0 0" xyz="0.0223306 -0.0314858 0.0862886 "/>
      <mass value="51.035413872"/>
      <inertia ixx="0.9828897092800002" ixy="-0.09742558032000001" ixz="-0.13834225656000002" iyy="1.2748434776000002" iyz="-0.05306685288000001" izz="1.1526389643200001"/>
    </inertial>
  </link>
  <link name="link_4">
    <visual>
      <origin rpy="0 0 0" xyz="0 0 0"/>
      <geometry>
        <mesh filename="package://fanuc_m710ic_support/meshes/m710ic50/visual/link_4.stl"/>
      </geometry>
      <material name="">
        <color rgba="0.96 0.76 0.13 1.0"/>
      </material>
    </visual>
    <collision>
      <origin rpy="0 0 0" xyz="0 0 0"/>
      <geometry>
        <mesh filename="package://fanuc_m710ic_support/meshes/m710ic50/collision/link_4.stl"/>
      </geometry>
    </collision>
    <inertial>
      <origin rpy="0 0 0" xyz="0.6828896 -0.0221656 0.0004727 "/>
      <mass value="17.620793232"/>
      <inertia ixx="0.06400465072" ixy="0.05340090288000001" ixz="-0.0005926230400000001" iyy="0.9059148952800001" iyz="-0.00032647296000000003" izz="0.9115343656000001"/>
    </inertial>
  </link>
  <link name="link_5">
    <visual>
      <origin rpy="0 0 0" xyz="0 0 0"/>
      <geometry>
        <mesh filename="package://fanuc_m710ic_support/meshes/m710ic50/visual/link_5.stl"/>
      </geometry>
      <material name="">
        <color rgba="0.96 0.76 0.13 1.0"/>
      </material>
    </visual>
    <collision>
      <origin rpy="0 0 0" xyz="0 0 0"/>
      <geometry>
        <mesh filename="package://fanuc_m710ic_support/meshes/m710ic50/collision/link_5.stl"/>
      </geometry>
    </collision>
    <inertial>
      <origin rpy="0 0 0" xyz="0.0384575 0.0039676 -0 "/>
      <mass value="5.04353144"/>
      <inertia ixx="0.018651968640000002" ixy="-0.00143201864" ixz="-0.0" iyy="0.02675220168" iyz="0.0" izz="0.028386463360000006"/>
    </inertial>
  </link>
  <link name="link_6">
    <visual>
      <origin rpy="0 0 0" xyz="0 0 0"/>
      <geometry>
        <mesh filename="package://fanuc_m710ic_support/meshes/m710ic50/visual/link_6.stl"/>
      </geometry>
      <material name="">
        <color rgba="0.15 0.15 0.15 1.0"/>
      </material>
    </visual>
    <collision>
      <origin rpy="0 0 0" xyz="0 0 0"/>
      <geometry>
        <mesh filename="package://fanuc_m710ic_support/meshes/m710ic50/collision/link_6.stl"/>
      </geometry>
    </collision>
    <inertial>
      <origin rpy="0 0 0" xyz="-0.0122228 0.0000157 0 "/>
      <mass value="0.26049297600000004"/>
      <inertia ixx="0.00050270464" ixy="1.048e-08" ixz="0.0" iyy="0.00026049088000000006" iyz="0.0" izz="0.00026042800000000005"/>
    </inertial>
  </link>
  <!-- joints: main serial chain -->
  <joint name="joint_1" type="revolute">
    <origin rpy="0 0 0" xyz="0 0 0.565"/>
    <parent link="base_link"/>
    <child link="link_1"/>
    <axis xyz="0 0 1"/>
    <limit effort="0" lower="-3.1415" upper="3.1415" velocity="2.7925"/>
  </joint>
  <joint name="joint_2" type="revolute">
    <origin rpy="0 0 0" xyz="0.150 0 0"/>
    <parent link="link_1"/>
    <child link="link_2"/>
    <axis xyz="0 1 0"/>
    <limit effort="0" lower="-1.5707" upper="2.3561" velocity="2.0943"/>
  </joint>
  <joint name="joint_3" type="revolute">
    <origin rpy="0 0 0" xyz="0 0 0.870"/>
    <parent link="link_2"/>
    <child link="link_3"/>
    <axis xyz="0 -1 0"/>
    <limit effort="0" lower="-2.7925" upper="4.8869" velocity="2.0943"/>
  </joint>
  <joint name="joint_4" type="revolute">
    <origin rpy="0 0 0" xyz="0 0 0.170"/>
    <parent link="link_3"/>
    <child link="link_4"/>
    <axis xyz="-1 0 0"/>
    <limit effort="0" lower="-6.2830" upper="6.2830" velocity="3.9269"/>
  </joint>
  <joint name="joint_5" type="revolute">
    <origin rpy="0 0 0" xyz="1.016 0 0"/>
    <parent link="link_4"/>
    <child link="link_5"/>
    <axis xyz="0 -1 0"/>
    <limit effort="0" lower="-2.1816" upper="2.1816" velocity="3.9269"/>
  </joint>
  <joint name="joint_6" type="revolute">
    <origin rpy="0 0 0" xyz="0.175 0 0"/>
    <parent link="link_5"/>
    <child link="link_6"/>
    <axis xyz="-1 0 0"/>
    <limit effort="0" lower="-6.2831" upper="6.2831" velocity="3.9269"/>
  </joint>
  <!-- ROS-Industrial 'base' frame: base_link to Fanuc World Coordinates transform -->
  <link name="base"/>
  <joint name="base_link-base" type="fixed">
    <origin rpy="0 0 0" xyz="0 0 0.565"/>
    <parent link="base_link"/>
    <child link="base"/>
  </joint>
  <!-- ROS-Industrial 'flange' frame: attachment point for EEF models -->
  <link name="flange"/>
  <joint name="joint_6-flange" type="fixed">
    <origin rpy="0 0 0" xyz="0 0 0"/>
    <parent link="link_6"/>
    <child link="flange"/>
  </joint>
  <!-- ROS-Industrial 'tool0' frame: all-zeros tool frame -->
  <link name="tool0"/>
  <joint name="link_6-tool0" type="fixed">
    <origin rpy="3.141592653589793 -1.5707963267948966 0" xyz="0 0 0"/>
    <parent link="flange"/>
    <child link="tool0"/>
  </joint>
</robot>

