<?xml version="1.0" ?>
<robot name="abb">
  <joint name="abb_joint_1" type="revolute">
    <parent link="abb_base_link"/>
    <child link="abb_link_1"/>
    <origin rpy="0 0 0" xyz="0     0     0.630"/>
    <axis xyz="0 0 1"/>
    <limit effort="1000.0" lower="-2.967" upper="2.967" velocity="5.027"/>
  </joint>
  <joint name="abb_joint_2" type="revolute">
    <parent link="abb_link_1"/>
    <child link="abb_link_2"/>
    <origin rpy="0 0 0" xyz="0.600 0 0"/>
    <axis xyz="0 1 0"/>
    <limit effort="1000.0" lower="-1.745" upper="2.269" velocity="4.189"/>
  </joint>
  <joint name="abb_joint_3" type="revolute">
    <parent link="abb_link_2"/>
    <child link="abb_link_3"/>
    <origin rpy="0 0 0" xyz="0 0 1.280"/>
    <axis xyz="0 1 0"/>
    <limit effort="1000.0" lower="-3.491" upper="1.222" velocity="5.236"/>
  </joint>
  <joint name="abb_joint_4" type="revolute">
    <parent link="abb_link_3"/>
    <child link="abb_link_4"/>
    <origin rpy="0 0 0" xyz="-0.6 0 0.200"/>
    <axis xyz="1 0 0"/>
    <limit effort="1000.0" lower="-4.712" upper="4.712" velocity="6.981"/>
  </joint>
  <joint name="abb_joint_5" type="revolute">
    <parent link="abb_link_4"/>
    <child link="abb_link_5"/>
    <origin rpy="0 0 0" xyz="2.192 0 0"/>
    <axis xyz="0 1 0"/>
    <limit effort="1000.0" lower="-2.269" upper="2.269" velocity="7.069"/>
  </joint>
  <joint name="abb_joint_6" type="revolute">
    <parent link="abb_link_5"/>
    <child link="abb_link_6"/>
    <origin rpy="0 0 0" xyz="0.200 0 0"/>
    <axis xyz="1 0 0"/>
    <limit effort="1000.0" lower="-6.283" upper="6.283" velocity="10.472"/>
  </joint>
  <joint name="abb_pedestal_JOINT_0" type="fixed">
    <parent link="abb_pedestal"/>
    <child link="abb_base_link"/>
    <origin rpy="0 0 0" xyz="0 0 0"/>
    <axis xyz="0 0 0"/>
    <limit effort="0" lower="0" upper="0" velocity="0"/>
  </joint>
  <link name="abb_base_link">
    <inertial>
      <mass value="13.7742"/>
      <origin rpy="0 0 0" xyz="0 0 0"/>
      <inertia ixx="0.101998" ixy="0.000495482" ixz="0.000311158" iyy="0.13969" iyz="-0.000245375" izz="0.130433"/>
    </inertial>
    <collision name="abb_base_link_fixed_joint_lump__collision_collision">
      <origin rpy="0 0 0" xyz="0 0 0"/>
      <geometry>
        <mesh filename="/home/iamnotedible/Motion-Primitive-Planning/simulation/gazebo_sim/model/6650s/meshes/collision/base_link.stl" scale="1 1 1"/>
      </geometry>
    </collision>
    <visual name="abb_base_link_fixed_joint_lump__visual_visual">
      <origin rpy="0 0 0" xyz="0 0 0"/>
      <geometry>
        <mesh filename="/home/iamnotedible/Motion-Primitive-Planning/simulation/gazebo_sim/model/6650s/meshes/visual/base_link.stl" scale="1 1 1"/>
      </geometry>
    </visual>
  </link>
  <link name="abb_pedestal">
    <inertial>
      <mass value="1"/>
      <origin rpy="0 0 0" xyz="0 0 0"/>
      <inertia ixx="0.145833" ixy="0" ixz="0" iyy="0.145833" iyz="0" izz="0.125"/>
    </inertial>
    <collision name="abb_collision">
      <origin rpy="0 0 0" xyz="0   0  -0.4"/>
      <geometry>
        <cylinder length="0.9" radius="0.2"/>
      </geometry>
    </collision>
    <visual name="abb_visual">
      <origin rpy="0 0 0" xyz="0   0  -0.5"/>
      <geometry>
        <cylinder length="1.0" radius="0.2"/>
      </geometry>
    </visual>
  </link>
  <link name="abb_link_1">
    <inertial>
      <mass value="11.8419"/>
      <origin rpy="0 0 0" xyz="0 0 0"/>
      <inertia ixx="0.11194" ixy="-4.54988e-05" ixz="0.000280961" iyy="0.0915159" iyz="-0.000109905" izz="0.0876456"/>
    </inertial>
    <collision name="abb_link_1_fixed_joint_lump__collision_collision">
      <origin rpy="0 0 0" xyz="0 0 0"/>
      <geometry>
        <mesh filename="/home/iamnotedible/Motion-Primitive-Planning/simulation/gazebo_sim/model/6650s/meshes/collision/link_1.stl" scale="1 1 1"/>
      </geometry>
    </collision>
    <visual name="abb_link_1_fixed_joint_lump__visual_visual">
      <origin rpy="0 0 0" xyz="0 0 0"/>
      <geometry>
        <mesh filename="/home/iamnotedible/Motion-Primitive-Planning/simulation/gazebo_sim/model/6650s/meshes/visual/link_1.stl" scale="1 1 1"/>
      </geometry>
    </visual>
  </link>
  <link name="abb_link_2">
    <inertial>
      <mass value="17.5394"/>
      <origin rpy="0 0 0" xyz="0 0 0"/>
      <inertia ixx="0.493558" ixy="1.32136e-05" ixz="0.000209024" iyy="0.462939" iyz="-0.00179901" izz="0.0894214"/>
    </inertial>
    <collision name="abb_link_2_fixed_joint_lump__collision_collision">
      <origin rpy="0 0 0" xyz="0 0 0"/>
      <geometry>
        <mesh filename="/home/iamnotedible/Motion-Primitive-Planning/simulation/gazebo_sim/model/6650s/meshes/collision/link_2.stl" scale="1 1 1"/>
      </geometry>
    </collision>
    <visual name="abb_link_2_fixed_joint_lump__visual_visual">
      <origin rpy="0 0 0" xyz="0 0 0"/>
      <geometry>
        <mesh filename="/home/iamnotedible/Motion-Primitive-Planning/simulation/gazebo_sim/model/6650s/meshes/visual/link_2.stl" scale="1 1 1"/>
      </geometry>
    </visual>
  </link>
  <link name="abb_link_3">
    <inertial>
      <mass value="7.46365"/>
      <origin rpy="0 0 0" xyz="0 0 0"/>
      <inertia ixx="0.0252424" ixy="0.000142737" ixz="-0.00565542" iyy="0.0906438" iyz="0.000142213" izz="0.0825079"/>
    </inertial>
    <collision name="abb_link_3_fixed_joint_lump__collision_collision">
      <origin rpy="0 0 0" xyz="0 0 0"/>
      <geometry>
        <mesh filename="/home/iamnotedible/Motion-Primitive-Planning/simulation/gazebo_sim/model/6650s/meshes/collision/link_3.stl" scale="1 1 1"/>
      </geometry>
    </collision>
    <visual name="abb_link_3_fixed_joint_lump__visual_visual">
      <origin rpy="0 0 0" xyz="0 0 0"/>
      <geometry>
        <mesh filename="/home/iamnotedible/Motion-Primitive-Planning/simulation/gazebo_sim/model/6650s/meshes/visual/link_3.stl" scale="1 1 1"/>
      </geometry>
    </visual>
  </link>
  <link name="abb_link_4">
    <inertial>
      <mass value="2.74436"/>
      <origin rpy="0 0 0" xyz="0 0 0"/>
      <inertia ixx="0.00573099" ixy="-0.000131119" ixz="0.000380232" iyy="0.0118352" iyz="-2.26565e-05" izz="0.0114428"/>
    </inertial>
    <collision name="abb_link_4_fixed_joint_lump__collision_collision">
      <origin rpy="0 0 0" xyz="0 0 0"/>
      <geometry>
        <mesh filename="/home/iamnotedible/Motion-Primitive-Planning/simulation/gazebo_sim/model/6650s/meshes/collision/link_4.stl" scale="1 1 1"/>
      </geometry>
    </collision>
    <visual name="abb_link_4_fixed_joint_lump__visual_visual">
      <origin rpy="0 0 0" xyz="0 0 0"/>
      <geometry>
        <mesh filename="/home/iamnotedible/Motion-Primitive-Planning/simulation/gazebo_sim/model/6650s/meshes/visual/link_4.stl" scale="1 1 1"/>
      </geometry>
    </visual>
  </link>
  <link name="abb_link_5">
    <inertial>
      <mass value="0.62953"/>
      <origin rpy="0 0 0" xyz="0 0 0"/>
      <inertia ixx="0.000502815" ixy="-1.03173e-05" ixz="-8.74347e-08" iyy="0.00108856" iyz="2.07657e-07" izz="0.000918873"/>
    </inertial>
    <collision name="abb_link_5_fixed_joint_lump__collision_collision">
      <origin rpy="0 0 0" xyz="0 0 0"/>
      <geometry>
        <mesh filename="/home/iamnotedible/Motion-Primitive-Planning/simulation/gazebo_sim/model/6650s/meshes/collision/link_5.stl" scale="1 1 1"/>
      </geometry>
    </collision>
    <visual name="abb_link_5_fixed_joint_lump__visual_visual">
      <origin rpy="0 0 0" xyz="0 0 0"/>
      <geometry>
        <mesh filename="/home/iamnotedible/Motion-Primitive-Planning/simulation/gazebo_sim/model/6650s/meshes/visual/link_5.stl" scale="1 1 1"/>
      </geometry>
    </visual>
  </link>
  <link name="abb_link_6">
    <inertial>
      <mass value="0.137"/>
      <origin rpy="0 0 0" xyz="0 0 0"/>
      <inertia ixx="0.001" ixy="0" ixz="0" iyy="0.001" iyz="0" izz="0.001"/>
    </inertial>
    <collision name="abb_link_6_fixed_joint_lump__collision_collision">
      <origin rpy="0 0 0" xyz="0 0 0"/>
      <geometry>
        <mesh filename="/home/iamnotedible/Motion-Primitive-Planning/simulation/gazebo_sim/model/6650s/meshes/collision/link_6.stl" scale="1 1 1"/>
      </geometry>
    </collision>
    <visual name="abb_link_6_fixed_joint_lump__visual_visual">
      <origin rpy="0 0 0" xyz="0 0 0"/>
      <geometry>
        <mesh filename="/home/iamnotedible/Motion-Primitive-Planning/simulation/gazebo_sim/model/6650s/meshes/visual/link_6.stl" scale="1 1 1"/>
      </geometry>
    </visual>
  </link>
  <gazebo>
    <static>true</static>
  </gazebo>
</robot>
