<?xml version='1.0'?>
<sdf version='1.7'>
  <model name='fanuc_m710ic'>
    <link name='base_link'>
      <inertial>
        <pose>-0.049408 -0.000217 0.119217 0 -0 0</pose>
        <mass>0.0669869</mass>
        <inertia>
          <ixx>178.098</ixx>
          <ixy>0.485529</ixy>
          <ixz>2.74836</ixz>
          <iyy>181.958</iyy>
          <iyz>-0.227367</iyz>
          <izz>289.762</izz>
        </inertia>
      </inertial>
      <visual name='base_link_visual'>
        <pose>0 0 0 0 -0 0</pose>
        <geometry>
          <mesh>
            <scale>1 1 1</scale>
            <uri>model://fanuc_m710ic/meshes/m710ic50/visual/base_link.stl</uri>
          </mesh>
        </geometry>
      </visual>
    </link>
    <joint name='joint_1' type='revolute'>
      <pose relative_to='base_link'>0 0 0.565 0 -0 0</pose>
      <parent>base_link</parent>
      <child>link_1</child>
      <axis>
        <xyz>0 0 1</xyz>
        <limit>
          <lower>-3.14159</lower>
          <upper>3.14159</upper>
          <effort>0</effort>
          <velocity>3.14159</velocity>
        </limit>
        <dynamics>
          <spring_reference>0</spring_reference>
          <spring_stiffness>0</spring_stiffness>
        </dynamics>
      </axis>
      <physics>
        <ode>
          <limit>
            <cfm>0</cfm>
            <erp>0.2</erp>
          </limit>
          <suspension>
            <cfm>0</cfm>
            <erp>0.2</erp>
          </suspension>
        </ode>
      </physics>
    </joint>
    <link name='link_1'>
      <pose relative_to='joint_1'>0 0 0 0 -0 0</pose>
      <inertial>
        <pose>0.051395 -0.007063 -0.105077 0 -0 0</pose>
        <mass>0.103669</mass>
        <inertia>
          <ixx>386.833</ixx>
          <ixy>-17.1225</ixy>
          <ixz>-25.9313</ixz>
          <iyy>329.743</iyy>
          <iyz>11.3692</iyz>
          <izz>413.927</izz>
        </inertia>
      </inertial>
      <visual name='link_1_visual'>
        <pose>0 0 0 0 -0 0</pose>
        <geometry>
          <mesh>
            <scale>1 1 1</scale>
            <uri>model://fanuc_m710ic/meshes/m710ic50/visual/link_1.stl</uri>
          </mesh>
        </geometry>
      </visual>
    </link>
    <joint name='joint_2' type='revolute'>
      <pose relative_to='link_1'>0.15 0 0 0 -0 0</pose>
      <parent>link_1</parent>
      <child>link_2</child>
      <axis>
        <xyz>0 1 0</xyz>
        <limit>
          <lower>-1.5708</lower>
          <upper>2.35619</upper>
          <effort>0</effort>
          <velocity>3.14159</velocity>
        </limit>
        <dynamics>
          <spring_reference>0</spring_reference>
          <spring_stiffness>0</spring_stiffness>
        </dynamics>
      </axis>
    </joint>
    <link name='link_2'>
      <pose relative_to='joint_2'>0 0 0 0 -0 0</pose>
      <inertial>
        <pose>0.002549 0.155353 0.461643 0 -0 0</pose>
        <mass>0.0586133</mass>
        <inertia>
          <ixx>806.449</ixx>
          <ixy>1.34891</ixy>
          <ixz>0.912</ixz>
          <iyy>824.408</iyy>
          <iyz>-26.0715</iyz>
          <izz>48.6071</izz>
        </inertia>
      </inertial>
      <visual name='link_2_visual'>
        <pose>0 0 0 0 -0 0</pose>
        <geometry>
          <mesh>
            <scale>1 1 1</scale>
            <uri>model://fanuc_m710ic/meshes/m710ic45m/visual/link_2.stl</uri>
          </mesh>
        </geometry>
      </visual>
    </link>
    <joint name='joint_3' type='revolute'>
      <pose relative_to='link_2'>0 0 1.15 0 -0 0</pose>
      <parent>link_2</parent>
      <child>link_3</child>
      <axis>
        <xyz>0 -1 0</xyz>
        <limit>
          <lower>-2.79253</lower>
          <upper>4.88692</upper>
          <effort>0</effort>
          <velocity>3.14159</velocity>
        </limit>
        <dynamics>
          <spring_reference>0</spring_reference>
          <spring_stiffness>0</spring_stiffness>
        </dynamics>
      </axis>
    </joint>
    <link name='link_3'>
      <pose relative_to='joint_3'>0 0 0 0 -0 0</pose>
      <inertial>
        <pose>0.022331 -0.031486 0.086289 0 -0 0</pose>
        <mass>0.0486979</mass>
        <inertia>
          <ixx>93.7872</ixx>
          <ixy>-9.29633</ixy>
          <ixz>-13.2006</ixz>
          <iyy>121.645</iyy>
          <iyz>-5.06363</iyz>
          <izz>109.985</izz>
        </inertia>
      </inertial>
      <visual name='link_3_visual'>
        <pose>0 0 0 0 -0 0</pose>
        <geometry>
          <mesh>
            <scale>1 1 1</scale>
            <uri>model://fanuc_m710ic/meshes/m710ic50/visual/link_3.stl</uri>
          </mesh>
        </geometry>
      </visual>
    </link>
    <joint name='joint_4' type='revolute'>
      <pose relative_to='link_3'>0 0 0.17 0 -0 0</pose>
      <parent>link_3</parent>
      <child>link_4</child>
      <axis>
        <xyz>-1 0 0</xyz>
        <limit>
          <lower>-6.98132</lower>
          <upper>6.98132</upper>
          <effort>0</effort>
          <velocity>4.36332</velocity>
        </limit>
        <dynamics>
          <spring_reference>0</spring_reference>
          <spring_stiffness>0</spring_stiffness>
        </dynamics>
      </axis>
    </joint>
    <link name='link_4'>
      <pose relative_to='joint_4'>0 0 0 0 -0 0</pose>
      <inertial>
        <pose>0.805982 -0.020805 0.000406 0 -0 0</pose>
        <mass>0.0240928</mass>
        <inertia>
          <ixx>8.92551</ixx>
          <ixy>9.76094</ixy>
          <ixz>-0.090163</ixz>
          <iyy>239.676</iyy>
          <iyz>-0.031016</iyz>
          <izz>240.442</izz>
        </inertia>
      </inertial>
      <visual name='link_4_visual'>
        <pose>0 0 0 0 -0 0</pose>
        <geometry>
          <mesh>
            <scale>1 1 1</scale>
            <uri>model://fanuc_m710ic/meshes/m710ic45m/visual/link_4.stl</uri>
          </mesh>
        </geometry>
      </visual>
    </link>
    <joint name='joint_5' type='revolute'>
      <pose relative_to='link_4'>1.295 0 0 0 -0 0</pose>
      <parent>link_4</parent>
      <child>link_5</child>
      <axis>
        <xyz>0 -1 0</xyz>
        <limit>
          <lower>-2.18166</lower>
          <upper>2.18166</upper>
          <effort>0</effort>
          <velocity>4.36332</velocity>
        </limit>
        <dynamics>
          <spring_reference>0</spring_reference>
          <spring_stiffness>0</spring_stiffness>
        </dynamics>
      </axis>
    </joint>
    <link name='link_5'>
      <pose relative_to='joint_5'>0 0 0 0 -0 0</pose>
      <inertial>
        <pose>0.038458 0.003968 0 0 -0 0</pose>
        <mass>0.00481253</mass>
        <inertia>
          <ixx>1.77977</ixx>
          <ixy>-0.136643</ixy>
          <ixz>0</ixz>
          <iyy>2.55269</iyy>
          <iyz>0</iyz>
          <izz>2.70863</izz>
        </inertia>
      </inertial>
      <visual name='link_5_visual'>
        <pose>0 0 0 0 -0 0</pose>
        <geometry>
          <mesh>
            <scale>1 1 1</scale>
            <uri>model://fanuc_m710ic/meshes/m710ic50/visual/link_5.stl</uri>
          </mesh>
        </geometry>
      </visual>
    </link>
    <joint name='joint_6' type='revolute'>
      <pose relative_to='link_5'>0.175 0 0 0 -0 0</pose>
      <parent>link_5</parent>
      <child>link_6</child>
      <axis>
        <xyz>-1 0 0</xyz>
        <limit>
          <lower>-6.98132</lower>
          <upper>6.98132</upper>
          <effort>0</effort>
          <velocity>6.28319</velocity>
        </limit>
        <dynamics>
          <spring_reference>0</spring_reference>
          <spring_stiffness>0</spring_stiffness>
        </dynamics>
      </axis>
    </joint>
    <link name='link_6'>
      <pose relative_to='joint_6'>0 0 0 0 -0 0</pose>
      <inertial>
        <pose>-0.012223 1.6e-05 0 0 -0 0</pose>
        <mass>0.000248562</mass>
        <inertia>
          <ixx>0.047968</ixx>
          <ixy>1e-06</ixy>
          <ixz>0</ixz>
          <iyy>0.024856</iyy>
          <iyz>0</iyz>
          <izz>0.02485</izz>
        </inertia>
      </inertial>
      <visual name='link_6_visual'>
        <pose>0 0 0 0 -0 0</pose>
        <geometry>
          <mesh>
            <scale>1 1 1</scale>
            <uri>model://fanuc_m710ic/meshes/m710ic50/visual/link_6.stl</uri>
          </mesh>
        </geometry>
      </visual>
    </link>

    <link name='paint_gun'>
      <!-- <pose>0.533 -0 0.8891 0 1.57079632679 0</pose> -->
      <pose relative_to='eef_joint'>0 0 0 0 1.5707963267948966 0</pose>
      <inertial>
        <pose>0 0 0 0 0 0</pose>
        <mass>0.137</mass>
        <inertia>
          <ixx>0.001</ixx>
          <ixy>0</ixy>
          <ixz>0</ixz>
          <iyy>0.001</iyy>
          <iyz>0</iyz>
          <izz>0.001</izz>
        </inertia>
      </inertial>
      <self_collide>0</self_collide>
      <enable_wind>0</enable_wind>
      <kinematic>0</kinematic>
      <visual name='paint_gun_visual'>
        <pose>0 0 0 0 -0 0</pose>
        <geometry>
          <mesh>
            <scale>0.001 0.001 0.001</scale>
            <uri>model://paint_gun.stl</uri>
          </mesh>
        </geometry>
        <material>
          <shader type='pixel'/>
        </material>
        <transparency>0</transparency>
        <cast_shadows>1</cast_shadows>
      </visual>
    </link>

    <!-- ROS-Industrial 'flange' frame: attachment point for EEF models -->
    <!-- <link name="flange"/>
    <joint name="joint_6-flange" type="fixed">
      <origin rpy="0 0 0" xyz="0 0 0"/>
      <parent link="link_6"/>
      <child link="flange"/>
    </joint> -->
    <!-- ROS-Industrial 'tool0' frame: all-zeros tool frame -->
    <!-- <link name="tool0"/>
    <joint name="link_6-tool0" type="fixed">
      <origin rpy="3.141592653589793 -1.5707963267948966 0" xyz="0 0 0"/>
      <parent link="flange"/>
      <child link="tool0"/>
    </joint> -->

    <joint name='eef_joint' type='revolute'>
      <pose relative_to='link_6'>0 0 0 0 -0 0</pose>
      <parent>link_6</parent>
      <child>paint_gun</child>
      <axis>
        <xyz>-1 0 0</xyz>
        <limit>
          <lower>0</lower>
          <upper>0</upper>
          <effort>0</effort>
          <velocity>0</velocity>
        </limit>
        <dynamics>
          <spring_reference>0</spring_reference>
          <spring_stiffness>0</spring_stiffness>
        </dynamics>
      </axis>
    </joint>
    <!-- <joint name='eef_joint' type='fixed'>
      <parent>link_6</parent>
      <child>paint_gun</child>
    </joint> -->

    <joint name='fix to ground' type='fixed'>
      <parent>world</parent>
      <child>base_link</child>
    </joint>

    <!-- <joint name='fix to ground' type='revolute'>
      <pose relative_to='world'>0 0 0 0 -0 0</pose>
      <parent>world</parent>
      <child>base_link</child>
      <axis>
        <xyz>-1 0 0</xyz>
        <limit>
          <lower>0</lower>
          <upper>0</upper>
          <effort>0</effort>
          <velocity>0</velocity>
        </limit>
        <dynamics>
          <spring_reference>0</spring_reference>
          <spring_stiffness>0</spring_stiffness>
        </dynamics>
      </axis>
    </joint> -->
    
    <static>0</static>
    <allow_auto_disable>1</allow_auto_disable>
  </model>
</sdf>
